=== CURRENT USER REQUEST ===\nHello
INFO:httpx:HTTP Request: POST https://europe-west4-aiplatform.googleapis.com/v1beta1/projects/gen-lang-client-0319023828/locations/europe-west4/reasoningEngines/3290583215235923968/sessions "HTTP/1.1 200 OK"
INFO:google_adk.google.adk.sessions.vertex_ai_session_service:Create Session response {'name': 'projects/1083364725815/locations/europe-west4/reasoningEngines/3290583215235923968/sessions/2991107583911133184/operations/3153822797877215232', 'metadata': {'@type': 'type.googleapis.com/google.cloud.aiplatform.v1beta1.CreateSessionOperationMetadata', 'genericMetadata': {'createTime': '2025-07-09T05:04:17.998658Z', 'updateTime': '2025-07-09T05:04:17.998658Z'}}}
INFO:httpx:HTTP Request: GET https://europe-west4-aiplatform.googleapis.com/v1beta1/projects/gen-lang-client-0319023828/locations/europe-west4/operations/3153822797877215232 "HTTP/1.1 200 OK"
INFO:httpx:HTTP Request: GET https://europe-west4-aiplatform.googleapis.com/v1beta1/projects/gen-lang-client-0319023828/locations/europe-west4/operations/3153822797877215232 "HTTP/1.1 200 OK"
INFO:httpx:HTTP Request: GET https://europe-west4-aiplatform.googleapis.com/v1beta1/projects/gen-lang-client-0319023828/locations/europe-west4/reasoningEngines/3290583215235923968/sessions/2991107583911133184 "HTTP/1.1 200 OK"
INFO:services.llm.vertex_adk_client:Created new ADK session: 2991107583911133184
INFO:httpx:HTTP Request: GET https://europe-west4-aiplatform.googleapis.com/v1beta1/projects/gen-lang-client-0319023828/locations/europe-west4/reasoningEngines/3290583215235923968/sessions/2991107583911133184 "HTTP/1.1 200 OK"
INFO:httpx:HTTP Request: GET https://europe-west4-aiplatform.googleapis.com/v1beta1/projects/gen-lang-client-0319023828/locations/europe-west4/reasoningEngines/3290583215235923968/sessions/2991107583911133184/events "HTTP/1.1 200 OK"
INFO:httpx:HTTP Request: POST https://europe-west4-aiplatform.googleapis.com/v1beta1/projects/gen-lang-client-0319023828/locations/europe-west4/reasoningEngines/3290583215235923968/sessions/2991107583911133184:appendEvent "HTTP/1.1 400 Bad Request"
Exception in thread Thread-3 (_asyncio_thread_main):
Traceback (most recent call last):
  File "/home/mica/miniconda3/envs/pegasus/lib/python3.13/threading.py", line 1043, in _bootstrap_inner
    self.run()
    ~~~~~~~~^^
  File "/home/mica/miniconda3/envs/pegasus/lib/python3.13/threading.py", line 994, in run
    self._target(*self._args, **self._kwargs)
    ~~~~~~~~~~~~^^^^^^^^^^^^^^^^^^^^^^^^^^^^^
  File "/home/mica/miniconda3/envs/pegasus/lib/python3.13/site-packages/google/adk/runners.py", line 144, in _asyncio_thread_main
    asyncio.run(_invoke_run_async())
    ~~~~~~~~~~~^^^^^^^^^^^^^^^^^^^^^
  File "/home/mica/miniconda3/envs/pegasus/lib/python3.13/asyncio/runners.py", line 195, in run
    return runner.run(main)
           ~~~~~~~~~~^^^^^^
  File "/home/mica/miniconda3/envs/pegasus/lib/python3.13/asyncio/runners.py", line 118, in run
    return self._loop.run_until_complete(task)
           ~~~~~~~~~~~~~~~~~~~~~~~~~~~~~^^^^^^
  File "uvloop/loop.pyx", line 1518, in uvloop.loop.Loop.run_until_complete
  File "/home/mica/miniconda3/envs/pegasus/lib/python3.13/site-packages/google/adk/runners.py", line 132, in _invoke_run_async
    async for event in self.run_async(
    ...<5 lines>...
      event_queue.put(event)
  File "/home/mica/miniconda3/envs/pegasus/lib/python3.13/site-packages/google/adk/runners.py", line 195, in run_async
    await self._append_new_message_to_session(
    ...<4 lines>...
    )
  File "/home/mica/miniconda3/envs/pegasus/lib/python3.13/site-packages/google/adk/runners.py", line 250, in _append_new_message_to_session
    await self.session_service.append_event(session=session, event=event)
  File "/home/mica/miniconda3/envs/pegasus/lib/python3.13/site-packages/google/adk/sessions/vertex_ai_session_service.py", line 301, in append_event
    await api_client.async_request(
    ...<3 lines>...
    )
  File "/home/mica/miniconda3/envs/pegasus/lib/python3.13/site-packages/google/genai/_api_client.py", line 1101, in async_request
    result = await self._async_request(http_request=http_request, stream=False)
             ^^^^^^^^^^^^^^^^^^^^^^^^^^^^^^^^^^^^^^^^^^^^^^^^^^^^^^^^^^^^^^^^^^
  File "/home/mica/miniconda3/envs/pegasus/lib/python3.13/site-packages/google/genai/_api_client.py", line 1046, in _async_request
    return await self._async_retry(  # type: ignore[no-any-return]
           ^^^^^^^^^^^^^^^^^^^^^^^^^^^^^^^^^^^^^^^^^^^^^^^^^^^^^^^
        self._async_request_once, http_request, stream
        ^^^^^^^^^^^^^^^^^^^^^^^^^^^^^^^^^^^^^^^^^^^^^^
    )
    ^
  File "/home/mica/miniconda3/envs/pegasus/lib/python3.13/site-packages/tenacity/asyncio/__init__.py", line 111, in __call__
    do = await self.iter(retry_state=retry_state)
         ^^^^^^^^^^^^^^^^^^^^^^^^^^^^^^^^^^^^^^^^
  File "/home/mica/miniconda3/envs/pegasus/lib/python3.13/site-packages/tenacity/asyncio/__init__.py", line 153, in iter
    result = await action(retry_state)
             ^^^^^^^^^^^^^^^^^^^^^^^^^
  File "/home/mica/miniconda3/envs/pegasus/lib/python3.13/site-packages/tenacity/_utils.py", line 99, in inner
    return call(*args, **kwargs)
  File "/home/mica/miniconda3/envs/pegasus/lib/python3.13/site-packages/tenacity/__init__.py", line 418, in exc_check
    raise retry_exc.reraise()
          ~~~~~~~~~~~~~~~~~^^
  File "/home/mica/miniconda3/envs/pegasus/lib/python3.13/site-packages/tenacity/__init__.py", line 185, in reraise
    raise self.last_attempt.result()
          ~~~~~~~~~~~~~~~~~~~~~~~~^^
  File "/home/mica/miniconda3/envs/pegasus/lib/python3.13/concurrent/futures/_base.py", line 449, in result
    return self.__get_result()
           ~~~~~~~~~~~~~~~~~^^
  File "/home/mica/miniconda3/envs/pegasus/lib/python3.13/concurrent/futures/_base.py", line 401, in __get_result
    raise self._exception
  File "/home/mica/miniconda3/envs/pegasus/lib/python3.13/site-packages/tenacity/asyncio/__init__.py", line 114, in __call__
    result = await fn(*args, **kwargs)
             ^^^^^^^^^^^^^^^^^^^^^^^^^
  File "/home/mica/miniconda3/envs/pegasus/lib/python3.13/site-packages/google/genai/_api_client.py", line 1038, in _async_request_once
    await errors.APIError.raise_for_async_response(client_response)
  File "/home/mica/miniconda3/envs/pegasus/lib/python3.13/site-packages/google/genai/errors.py", line 155, in raise_for_async_response
    raise ClientError(status_code, response_json, response)
google.genai.errors.ClientError: 400 INVALID_ARGUMENT. {'error': {'code': 400, 'message': "Invalid value at 'event.content.parts[0]' (oneof), oneof field 'data' is already set. Cannot set 'file_data'\nInvalid value at 'event.content.parts[0]' (oneof), oneof field 'data' is already set. Cannot set 'function_response'\nInvalid value at 'event.content.parts[0]' (oneof), oneof field 'data' is already set. Cannot set 'text'", 'status': 'INVALID_ARGUMENT', 'details': [{'@type': 'type.googleapis.com/google.rpc.BadRequest', 'fieldViolations': [{'field': 'event.content.parts[0]', 'description': "Invalid value at 'event.content.parts[0]' (oneof), oneof field 'data' is already set. Cannot set 'file_data'"}, {'field': 'event.content.parts[0]', 'description': "Invalid value at 'event.content.parts[0]' (oneof), oneof field 'data' is already set. Cannot set 'function_response'"}, {'field': 'event.content.parts[0]', 'description': "Invalid value at 'event.content.parts[0]' (oneof), oneof field 'data' is already set. Cannot set 'text'"}]}]}}
ERROR:services.llm.vertex_adk_client:ADK runner error: No final response received from ADK agent
INFO:api.chat_router_v2:Chat V2 processed successfully: 2934 chars in 8858.4ms
INFO:     192.168.1.10:39112 - "POST /chat/v2/ HTTP/1.1" 500 Internal Server Error
ERROR:    Exception in ASGI application
  + Exception Group Traceback (most recent call last):
  |   File "/home/mica/miniconda3/envs/pegasus/lib/python3.13/site-packages/starlette/_utils.py", line 76, in collapse_excgroups
  |     yield
  |   File "/home/mica/miniconda3/envs/pegasus/lib/python3.13/site-packages/starlette/middleware/base.py", line 177, in __call__
  |     async with anyio.create_task_group() as task_group:
  |                ~~~~~~~~~~~~~~~~~~~~~~~^^
  |   File "/home/mica/miniconda3/envs/pegasus/lib/python3.13/site-packages/anyio/_backends/_asyncio.py", line 772, in __aexit__
  |     raise BaseExceptionGroup(
  |         "unhandled errors in a TaskGroup", self._exceptions
  |     ) from None
  | ExceptionGroup: unhandled errors in a TaskGroup (1 sub-exception)
  +-+---------------- 1 ----------------
    | Traceback (most recent call last):
    |   File "/home/mica/miniconda3/envs/pegasus/lib/python3.13/site-packages/uvicorn/protocols/http/httptools_impl.py", line 409, in run_asgi
    |     result = await app(  # type: ignore[func-returns-value]
    |              ^^^^^^^^^^^^^^^^^^^^^^^^^^^^^^^^^^^^^^^^^^^^^^
    |         self.scope, self.receive, self.send
    |         ^^^^^^^^^^^^^^^^^^^^^^^^^^^^^^^^^^^
    |     )
    |     ^
    |   File "/home/mica/miniconda3/envs/pegasus/lib/python3.13/site-packages/uvicorn/middleware/proxy_headers.py", line 60, in __call__
    |     return await self.app(scope, receive, send)
    |            ^^^^^^^^^^^^^^^^^^^^^^^^^^^^^^^^^^^^
    |   File "/home/mica/miniconda3/envs/pegasus/lib/python3.13/site-packages/fastapi/applications.py", line 1054, in __call__
    |     await super().__call__(scope, receive, send)
    |   File "/home/mica/miniconda3/envs/pegasus/lib/python3.13/site-packages/starlette/applications.py", line 112, in __call__
    |     await self.middleware_stack(scope, receive, send)
    |   File "/home/mica/miniconda3/envs/pegasus/lib/python3.13/site-packages/starlette/middleware/errors.py", line 187, in __call__
    |     raise exc
    |   File "/home/mica/miniconda3/envs/pegasus/lib/python3.13/site-packages/starlette/middleware/errors.py", line 165, in __call__
    |     await self.app(scope, receive, _send)
    |   File "/home/mica/miniconda3/envs/pegasus/lib/python3.13/site-packages/starlette/middleware/base.py", line 176, in __call__
    |     with recv_stream, send_stream, collapse_excgroups():
    |                                    ~~~~~~~~~~~~~~~~~~^^
    |   File "/home/mica/miniconda3/envs/pegasus/lib/python3.13/contextlib.py", line 162, in __exit__
    |     self.gen.throw(value)
    |     ~~~~~~~~~~~~~~^^^^^^^
    |   File "/home/mica/miniconda3/envs/pegasus/lib/python3.13/site-packages/starlette/_utils.py", line 82, in collapse_excgroups
    |     raise exc
    |   File "/home/mica/miniconda3/envs/pegasus/lib/python3.13/site-packages/starlette/middleware/base.py", line 178, in __call__
    |     response = await self.dispatch_func(request, call_next)
    |                ^^^^^^^^^^^^^^^^^^^^^^^^^^^^^^^^^^^^^^^^^^^^
    |   File "/home/mica/Desktop/pegasus/backend/middleware/logging_middleware.py", line 289, in dispatch
    |     return await super().dispatch(request, call_next)
    |            ^^^^^^^^^^^^^^^^^^^^^^^^^^^^^^^^^^^^^^^^^^
    |   File "/home/mica/Desktop/pegasus/backend/middleware/logging_middleware.py", line 85, in dispatch
    |     response = await call_next(request)
    |                ^^^^^^^^^^^^^^^^^^^^^^^^
    |   File "/home/mica/miniconda3/envs/pegasus/lib/python3.13/site-packages/starlette/middleware/base.py", line 156, in call_next
    |     raise app_exc
    |   File "/home/mica/miniconda3/envs/pegasus/lib/python3.13/site-packages/starlette/middleware/base.py", line 141, in coro
    |     await self.app(scope, receive_or_disconnect, send_no_error)
    |   File "/home/mica/miniconda3/envs/pegasus/lib/python3.13/site-packages/starlette/middleware/exceptions.py", line 62, in __call__
    |     await wrap_app_handling_exceptions(self.app, conn)(scope, receive, send)
    |   File "/home/mica/miniconda3/envs/pegasus/lib/python3.13/site-packages/starlette/_exception_handler.py", line 53, in wrapped_app
    |     raise exc
    |   File "/home/mica/miniconda3/envs/pegasus/lib/python3.13/site-packages/starlette/_exception_handler.py", line 42, in wrapped_app
    |     await app(scope, receive, sender)
    |   File "/home/mica/miniconda3/envs/pegasus/lib/python3.13/site-packages/starlette/routing.py", line 714, in __call__
    |     await self.middleware_stack(scope, receive, send)
    |   File "/home/mica/miniconda3/envs/pegasus/lib/python3.13/site-packages/starlette/routing.py", line 734, in app
    |     await route.handle(scope, receive, send)
    |   File "/home/mica/miniconda3/envs/pegasus/lib/python3.13/site-packages/starlette/routing.py", line 288, in handle
    |     await self.app(scope, receive, send)
    |   File "/home/mica/miniconda3/envs/pegasus/lib/python3.13/site-packages/starlette/routing.py", line 76, in app
    |     await wrap_app_handling_exceptions(app, request)(scope, receive, send)
    |   File "/home/mica/miniconda3/envs/pegasus/lib/python3.13/site-packages/starlette/_exception_handler.py", line 53, in wrapped_app
    |     raise exc
    |   File "/home/mica/miniconda3/envs/pegasus/lib/python3.13/site-packages/starlette/_exception_handler.py", line 42, in wrapped_app
    |     await app(scope, receive, sender)
    |   File "/home/mica/miniconda3/envs/pegasus/lib/python3.13/site-packages/starlette/routing.py", line 73, in app
    |     response = await f(request)
    |                ^^^^^^^^^^^^^^^^
    |   File "/home/mica/miniconda3/envs/pegasus/lib/python3.13/site-packages/fastapi/routing.py", line 327, in app
    |     content = await serialize_response(
    |               ^^^^^^^^^^^^^^^^^^^^^^^^^
    |     ...<9 lines>...
    |     )
    |     ^
    |   File "/home/mica/miniconda3/envs/pegasus/lib/python3.13/site-packages/fastapi/routing.py", line 181, in serialize_response
    |     return field.serialize(
    |            ~~~~~~~~~~~~~~~^
    |         value,
    |         ^^^^^^
    |     ...<5 lines>...
    |         exclude_none=exclude_none,
    |         ^^^^^^^^^^^^^^^^^^^^^^^^^^
    |     )
    |     ^
    |   File "/home/mica/miniconda3/envs/pegasus/lib/python3.13/site-packages/fastapi/_compat.py", line 152, in serialize
    |     return self._type_adapter.dump_python(
    |            ~~~~~~~~~~~~~~~~~~~~~~~~~~~~~~^
    |         value,
    |         ^^^^^^
    |     ...<6 lines>...
    |         exclude_none=exclude_none,
    |         ^^^^^^^^^^^^^^^^^^^^^^^^^^
    |     )
    |     ^
    |   File "/home/mica/miniconda3/envs/pegasus/lib/python3.13/site-packages/pydantic/type_adapter.py", line 572, in dump_python
    |     return self.serializer.to_python(
    |            ~~~~~~~~~~~~~~~~~~~~~~~~~^
    |         instance,
    |         ^^^^^^^^^
    |     ...<11 lines>...
    |         context=context,
    |         ^^^^^^^^^^^^^^^^
    |     )
    |     ^
    | pydantic_core._pydantic_core.PydanticSerializationError: Unable to serialize unknown type: <class 'neo4j.time.DateTime'>
    +------------------------------------

During handling of the above exception, another exception occurred:

Traceback (most recent call last):
  File "/home/mica/miniconda3/envs/pegasus/lib/python3.13/site-packages/uvicorn/protocols/http/httptools_impl.py", line 409, in run_asgi
    result = await app(  # type: ignore[func-returns-value]
             ^^^^^^^^^^^^^^^^^^^^^^^^^^^^^^^^^^^^^^^^^^^^^^
        self.scope, self.receive, self.send
        ^^^^^^^^^^^^^^^^^^^^^^^^^^^^^^^^^^^
    )
    ^
  File "/home/mica/miniconda3/envs/pegasus/lib/python3.13/site-packages/uvicorn/middleware/proxy_headers.py", line 60, in __call__
    return await self.app(scope, receive, send)
           ^^^^^^^^^^^^^^^^^^^^^^^^^^^^^^^^^^^^
  File "/home/mica/miniconda3/envs/pegasus/lib/python3.13/site-packages/fastapi/applications.py", line 1054, in __call__
    await super().__call__(scope, receive, send)
  File "/home/mica/miniconda3/envs/pegasus/lib/python3.13/site-packages/starlette/applications.py", line 112, in __call__
    await self.middleware_stack(scope, receive, send)
  File "/home/mica/miniconda3/envs/pegasus/lib/python3.13/site-packages/starlette/middleware/errors.py", line 187, in __call__
    raise exc
  File "/home/mica/miniconda3/envs/pegasus/lib/python3.13/site-packages/starlette/middleware/errors.py", line 165, in __call__
    await self.app(scope, receive, _send)
  File "/home/mica/miniconda3/envs/pegasus/lib/python3.13/site-packages/starlette/middleware/base.py", line 176, in __call__
    with recv_stream, send_stream, collapse_excgroups():
                                   ~~~~~~~~~~~~~~~~~~^^
  File "/home/mica/miniconda3/envs/pegasus/lib/python3.13/contextlib.py", line 162, in __exit__
    self.gen.throw(value)
    ~~~~~~~~~~~~~~^^^^^^^
  File "/home/mica/miniconda3/envs/pegasus/lib/python3.13/site-packages/starlette/_utils.py", line 82, in collapse_excgroups
    raise exc
  File "/home/mica/miniconda3/envs/pegasus/lib/python3.13/site-packages/starlette/middleware/base.py", line 178, in __call__
    response = await self.dispatch_func(request, call_next)
               ^^^^^^^^^^^^^^^^^^^^^^^^^^^^^^^^^^^^^^^^^^^^
  File "/home/mica/Desktop/pegasus/backend/middleware/logging_middleware.py", line 289, in dispatch
    return await super().dispatch(request, call_next)
           ^^^^^^^^^^^^^^^^^^^^^^^^^^^^^^^^^^^^^^^^^^
  File "/home/mica/Desktop/pegasus/backend/middleware/logging_middleware.py", line 85, in dispatch
    response = await call_next(request)
               ^^^^^^^^^^^^^^^^^^^^^^^^
  File "/home/mica/miniconda3/envs/pegasus/lib/python3.13/site-packages/starlette/middleware/base.py", line 156, in call_next
    raise app_exc
  File "/home/mica/miniconda3/envs/pegasus/lib/python3.13/site-packages/starlette/middleware/base.py", line 141, in coro
    await self.app(scope, receive_or_disconnect, send_no_error)
  File "/home/mica/miniconda3/envs/pegasus/lib/python3.13/site-packages/starlette/middleware/exceptions.py", line 62, in __call__
    await wrap_app_handling_exceptions(self.app, conn)(scope, receive, send)
  File "/home/mica/miniconda3/envs/pegasus/lib/python3.13/site-packages/starlette/_exception_handler.py", line 53, in wrapped_app
    raise exc
  File "/home/mica/miniconda3/envs/pegasus/lib/python3.13/site-packages/starlette/_exception_handler.py", line 42, in wrapped_app
    await app(scope, receive, sender)
  File "/home/mica/miniconda3/envs/pegasus/lib/python3.13/site-packages/starlette/routing.py", line 714, in __call__
    await self.middleware_stack(scope, receive, send)
  File "/home/mica/miniconda3/envs/pegasus/lib/python3.13/site-packages/starlette/routing.py", line 734, in app
    await route.handle(scope, receive, send)
  File "/home/mica/miniconda3/envs/pegasus/lib/python3.13/site-packages/starlette/routing.py", line 288, in handle
    await self.app(scope, receive, send)
  File "/home/mica/miniconda3/envs/pegasus/lib/python3.13/site-packages/starlette/routing.py", line 76, in app
    await wrap_app_handling_exceptions(app, request)(scope, receive, send)
  File "/home/mica/miniconda3/envs/pegasus/lib/python3.13/site-packages/starlette/_exception_handler.py", line 53, in wrapped_app
    raise exc
  File "/home/mica/miniconda3/envs/pegasus/lib/python3.13/site-packages/starlette/_exception_handler.py", line 42, in wrapped_app
    await app(scope, receive, sender)
  File "/home/mica/miniconda3/envs/pegasus/lib/python3.13/site-packages/starlette/routing.py", line 73, in app
    response = await f(request)
               ^^^^^^^^^^^^^^^^
  File "/home/mica/miniconda3/envs/pegasus/lib/python3.13/site-packages/fastapi/routing.py", line 327, in app
    content = await serialize_response(
              ^^^^^^^^^^^^^^^^^^^^^^^^^
    ...<9 lines>...
    )
    ^
  File "/home/mica/miniconda3/envs/pegasus/lib/python3.13/site-packages/fastapi/routing.py", line 181, in serialize_response
    return field.serialize(
           ~~~~~~~~~~~~~~~^
        value,
        ^^^^^^
    ...<5 lines>...
        exclude_none=exclude_none,
        ^^^^^^^^^^^^^^^^^^^^^^^^^^
    )
    ^
  File "/home/mica/miniconda3/envs/pegasus/lib/python3.13/site-packages/fastapi/_compat.py", line 152, in serialize
    return self._type_adapter.dump_python(
           ~~~~~~~~~~~~~~~~~~~~~~~~~~~~~~^
        value,
        ^^^^^^
    ...<6 lines>...
        exclude_none=exclude_none,
        ^^^^^^^^^^^^^^^^^^^^^^^^^^
    )
    ^
  File "/home/mica/miniconda3/envs/pegasus/lib/python3.13/site-packages/pydantic/type_adapter.py", line 572, in dump_python
    return self.serializer.to_python(
           ~~~~~~~~~~~~~~~~~~~~~~~~~^
        instance,
        ^^^^^^^^^
    ...<11 lines>...
        context=context,
        ^^^^^^^^^^^^^^^^
    )
    ^
pydantic_core._pydantic_core.PydanticSerializationError: Unable to serialize unknown type: <class 'neo4j.time.DateTime'>

